[2024-11-15 20:37:51,705] 97 werkzeug - INFO - [31m[1mWARNING: This is a development server. Do not use it in a production deployment. Use a production WSGI server instead.[0m
 * Running on all addresses (0.0.0.0)
 * Running on http://127.0.0.1:5050
 * Running on http://140.203.84.251:5050
[2024-11-15 20:37:51,706] 97 werkzeug - INFO - [33mPress CTRL+C to quit[0m
[2024-11-15 20:38:05,510] 97 werkzeug - INFO - 127.0.0.1 - - [15/Nov/2024 20:38:05] "GET / HTTP/1.1" 200 -
[2024-11-15 20:38:05,545] 97 werkzeug - INFO - 127.0.0.1 - - [15/Nov/2024 20:38:05] "[33mGET /favicon.ico HTTP/1.1[0m" 404 -
[2024-11-15 20:38:45,746] 97 werkzeug - INFO - 127.0.0.1 - - [15/Nov/2024 20:38:45] "GET /predictdata HTTP/1.1" 200 -
[2024-11-15 20:39:01,157] 838 app - ERROR - Exception on /predictdata [POST]
Traceback (most recent call last):
  File "/Users/dhruvshrinet/Desktop/ML PROJECT/src/utils.py", line 56, in load_object
    with open(file_path, "rb") as file_obj:
         ^^^^^^^^^^^^^^^^^^^^^
FileNotFoundError: [Errno 2] No such file or directory: 'artifacts/preprocessor.pkl'

During handling of the above exception, another exception occurred:

Traceback (most recent call last):
  File "/Users/dhruvshrinet/Desktop/ML PROJECT/src/pipeline/predict_pipeline.py", line 15, in predict
    preprocessor = load_object(file_path=preprocessor_path)
                   ^^^^^^^^^^^^^^^^^^^^^^^^^^^^^^^^^^^^^^^^
  File "/Users/dhruvshrinet/Desktop/ML PROJECT/src/utils.py", line 60, in load_object
    raise CustomException(e, sys)
src.exception.CustomException: Error occured in python script [/Users/dhruvshrinet/Desktop/ML PROJECT/src/utils.py] line number[56] error message[[Errno 2] No such file or directory: 'artifacts/preprocessor.pkl']

During handling of the above exception, another exception occurred:

Traceback (most recent call last):
  File "/Users/dhruvshrinet/Desktop/ML PROJECT/.venv/lib/python3.11/site-packages/flask/app.py", line 1473, in wsgi_app
    response = self.full_dispatch_request()
               ^^^^^^^^^^^^^^^^^^^^^^^^^^^^
  File "/Users/dhruvshrinet/Desktop/ML PROJECT/.venv/lib/python3.11/site-packages/flask/app.py", line 882, in full_dispatch_request
    rv = self.handle_user_exception(e)
         ^^^^^^^^^^^^^^^^^^^^^^^^^^^^^
  File "/Users/dhruvshrinet/Desktop/ML PROJECT/.venv/lib/python3.11/site-packages/flask/app.py", line 880, in full_dispatch_request
    rv = self.dispatch_request()
         ^^^^^^^^^^^^^^^^^^^^^^^
  File "/Users/dhruvshrinet/Desktop/ML PROJECT/.venv/lib/python3.11/site-packages/flask/app.py", line 865, in dispatch_request
    return self.ensure_sync(self.view_functions[rule.endpoint])(**view_args)  # type: ignore[no-any-return]
           ^^^^^^^^^^^^^^^^^^^^^^^^^^^^^^^^^^^^^^^^^^^^^^^^^^^^^^^^^^^^^^^^^
  File "/Users/dhruvshrinet/Desktop/ML PROJECT/app.py", line 37, in predict_datapoint
    results=predict_pipeline.predict(pred_df)
            ^^^^^^^^^^^^^^^^^^^^^^^^^^^^^^^^^
  File "/Users/dhruvshrinet/Desktop/ML PROJECT/src/pipeline/predict_pipeline.py", line 20, in predict
    raise CustomException(e,sys)
src.exception.CustomException: Error occured in python script [/Users/dhruvshrinet/Desktop/ML PROJECT/src/pipeline/predict_pipeline.py] line number[15] error message[Error occured in python script [/Users/dhruvshrinet/Desktop/ML PROJECT/src/utils.py] line number[56] error message[[Errno 2] No such file or directory: 'artifacts/preprocessor.pkl']]
[2024-11-15 20:39:01,159] 97 werkzeug - INFO - 127.0.0.1 - - [15/Nov/2024 20:39:01] "[35m[1mPOST /predictdata HTTP/1.1[0m" 500 -
[2024-11-15 20:39:52,560] 838 app - ERROR - Exception on /predictdata [POST]
Traceback (most recent call last):
  File "/Users/dhruvshrinet/Desktop/ML PROJECT/src/utils.py", line 56, in load_object
    with open(file_path, "rb") as file_obj:
         ^^^^^^^^^^^^^^^^^^^^^
FileNotFoundError: [Errno 2] No such file or directory: 'artifacts/preprocessor.pkl'

During handling of the above exception, another exception occurred:

Traceback (most recent call last):
  File "/Users/dhruvshrinet/Desktop/ML PROJECT/src/pipeline/predict_pipeline.py", line 15, in predict
    preprocessor = load_object(file_path=preprocessor_path)
                   ^^^^^^^^^^^^^^^^^^^^^^^^^^^^^^^^^^^^^^^^
  File "/Users/dhruvshrinet/Desktop/ML PROJECT/src/utils.py", line 60, in load_object
    raise CustomException(e, sys)
src.exception.CustomException: Error occured in python script [/Users/dhruvshrinet/Desktop/ML PROJECT/src/utils.py] line number[56] error message[[Errno 2] No such file or directory: 'artifacts/preprocessor.pkl']

During handling of the above exception, another exception occurred:

Traceback (most recent call last):
  File "/Users/dhruvshrinet/Desktop/ML PROJECT/.venv/lib/python3.11/site-packages/flask/app.py", line 1473, in wsgi_app
    response = self.full_dispatch_request()
               ^^^^^^^^^^^^^^^^^^^^^^^^^^^^
  File "/Users/dhruvshrinet/Desktop/ML PROJECT/.venv/lib/python3.11/site-packages/flask/app.py", line 882, in full_dispatch_request
    rv = self.handle_user_exception(e)
         ^^^^^^^^^^^^^^^^^^^^^^^^^^^^^
  File "/Users/dhruvshrinet/Desktop/ML PROJECT/.venv/lib/python3.11/site-packages/flask/app.py", line 880, in full_dispatch_request
    rv = self.dispatch_request()
         ^^^^^^^^^^^^^^^^^^^^^^^
  File "/Users/dhruvshrinet/Desktop/ML PROJECT/.venv/lib/python3.11/site-packages/flask/app.py", line 865, in dispatch_request
    return self.ensure_sync(self.view_functions[rule.endpoint])(**view_args)  # type: ignore[no-any-return]
           ^^^^^^^^^^^^^^^^^^^^^^^^^^^^^^^^^^^^^^^^^^^^^^^^^^^^^^^^^^^^^^^^^
  File "/Users/dhruvshrinet/Desktop/ML PROJECT/app.py", line 37, in predict_datapoint
    results=predict_pipeline.predict(pred_df)
            ^^^^^^^^^^^^^^^^^^^^^^^^^^^^^^^^^
  File "/Users/dhruvshrinet/Desktop/ML PROJECT/src/pipeline/predict_pipeline.py", line 20, in predict
    raise CustomException(e,sys)
src.exception.CustomException: Error occured in python script [/Users/dhruvshrinet/Desktop/ML PROJECT/src/pipeline/predict_pipeline.py] line number[15] error message[Error occured in python script [/Users/dhruvshrinet/Desktop/ML PROJECT/src/utils.py] line number[56] error message[[Errno 2] No such file or directory: 'artifacts/preprocessor.pkl']]
[2024-11-15 20:39:52,562] 97 werkzeug - INFO - 127.0.0.1 - - [15/Nov/2024 20:39:52] "[35m[1mPOST /predictdata HTTP/1.1[0m" 500 -
[2024-11-15 20:39:55,589] 838 app - ERROR - Exception on /predictdata [POST]
Traceback (most recent call last):
  File "/Users/dhruvshrinet/Desktop/ML PROJECT/src/utils.py", line 56, in load_object
    with open(file_path, "rb") as file_obj:
         ^^^^^^^^^^^^^^^^^^^^^
FileNotFoundError: [Errno 2] No such file or directory: 'artifacts/preprocessor.pkl'

During handling of the above exception, another exception occurred:

Traceback (most recent call last):
  File "/Users/dhruvshrinet/Desktop/ML PROJECT/src/pipeline/predict_pipeline.py", line 15, in predict
    preprocessor = load_object(file_path=preprocessor_path)
                   ^^^^^^^^^^^^^^^^^^^^^^^^^^^^^^^^^^^^^^^^
  File "/Users/dhruvshrinet/Desktop/ML PROJECT/src/utils.py", line 60, in load_object
    raise CustomException(e, sys)
src.exception.CustomException: Error occured in python script [/Users/dhruvshrinet/Desktop/ML PROJECT/src/utils.py] line number[56] error message[[Errno 2] No such file or directory: 'artifacts/preprocessor.pkl']

During handling of the above exception, another exception occurred:

Traceback (most recent call last):
  File "/Users/dhruvshrinet/Desktop/ML PROJECT/.venv/lib/python3.11/site-packages/flask/app.py", line 1473, in wsgi_app
    response = self.full_dispatch_request()
               ^^^^^^^^^^^^^^^^^^^^^^^^^^^^
  File "/Users/dhruvshrinet/Desktop/ML PROJECT/.venv/lib/python3.11/site-packages/flask/app.py", line 882, in full_dispatch_request
    rv = self.handle_user_exception(e)
         ^^^^^^^^^^^^^^^^^^^^^^^^^^^^^
  File "/Users/dhruvshrinet/Desktop/ML PROJECT/.venv/lib/python3.11/site-packages/flask/app.py", line 880, in full_dispatch_request
    rv = self.dispatch_request()
         ^^^^^^^^^^^^^^^^^^^^^^^
  File "/Users/dhruvshrinet/Desktop/ML PROJECT/.venv/lib/python3.11/site-packages/flask/app.py", line 865, in dispatch_request
    return self.ensure_sync(self.view_functions[rule.endpoint])(**view_args)  # type: ignore[no-any-return]
           ^^^^^^^^^^^^^^^^^^^^^^^^^^^^^^^^^^^^^^^^^^^^^^^^^^^^^^^^^^^^^^^^^
  File "/Users/dhruvshrinet/Desktop/ML PROJECT/app.py", line 37, in predict_datapoint
    results=predict_pipeline.predict(pred_df)
            ^^^^^^^^^^^^^^^^^^^^^^^^^^^^^^^^^
  File "/Users/dhruvshrinet/Desktop/ML PROJECT/src/pipeline/predict_pipeline.py", line 20, in predict
    raise CustomException(e,sys)
src.exception.CustomException: Error occured in python script [/Users/dhruvshrinet/Desktop/ML PROJECT/src/pipeline/predict_pipeline.py] line number[15] error message[Error occured in python script [/Users/dhruvshrinet/Desktop/ML PROJECT/src/utils.py] line number[56] error message[[Errno 2] No such file or directory: 'artifacts/preprocessor.pkl']]
[2024-11-15 20:39:55,590] 97 werkzeug - INFO - 127.0.0.1 - - [15/Nov/2024 20:39:55] "[35m[1mPOST /predictdata HTTP/1.1[0m" 500 -
[2024-11-15 20:40:49,333] 97 werkzeug - INFO - 127.0.0.1 - - [15/Nov/2024 20:40:49] "GET /predictdata HTTP/1.1" 200 -
[2024-11-15 20:40:51,122] 97 werkzeug - INFO - 127.0.0.1 - - [15/Nov/2024 20:40:51] "GET /predictdata HTTP/1.1" 200 -
[2024-11-15 20:40:51,822] 97 werkzeug - INFO - 127.0.0.1 - - [15/Nov/2024 20:40:51] "GET /predictdata HTTP/1.1" 200 -
[2024-11-15 20:40:52,071] 97 werkzeug - INFO - 127.0.0.1 - - [15/Nov/2024 20:40:52] "GET /predictdata HTTP/1.1" 200 -
[2024-11-15 20:40:52,280] 97 werkzeug - INFO - 127.0.0.1 - - [15/Nov/2024 20:40:52] "GET /predictdata HTTP/1.1" 200 -
[2024-11-15 20:40:53,080] 97 werkzeug - INFO - 127.0.0.1 - - [15/Nov/2024 20:40:53] "GET /predictdata HTTP/1.1" 200 -
[2024-11-15 20:40:54,331] 97 werkzeug - INFO - 127.0.0.1 - - [15/Nov/2024 20:40:54] "GET /predictdata HTTP/1.1" 200 -
[2024-11-15 20:41:02,693] 838 app - ERROR - Exception on /predictdata [POST]
Traceback (most recent call last):
  File "/Users/dhruvshrinet/Desktop/ML PROJECT/src/utils.py", line 56, in load_object
    with open(file_path, "rb") as file_obj:
         ^^^^^^^^^^^^^^^^^^^^^
FileNotFoundError: [Errno 2] No such file or directory: 'artifacts/preprocessor.pkl'

During handling of the above exception, another exception occurred:

Traceback (most recent call last):
  File "/Users/dhruvshrinet/Desktop/ML PROJECT/src/pipeline/predict_pipeline.py", line 15, in predict
    preprocessor = load_object(file_path=preprocessor_path)
                   ^^^^^^^^^^^^^^^^^^^^^^^^^^^^^^^^^^^^^^^^
  File "/Users/dhruvshrinet/Desktop/ML PROJECT/src/utils.py", line 60, in load_object
    raise CustomException(e, sys)
src.exception.CustomException: Error occured in python script [/Users/dhruvshrinet/Desktop/ML PROJECT/src/utils.py] line number[56] error message[[Errno 2] No such file or directory: 'artifacts/preprocessor.pkl']

During handling of the above exception, another exception occurred:

Traceback (most recent call last):
  File "/Users/dhruvshrinet/Desktop/ML PROJECT/.venv/lib/python3.11/site-packages/flask/app.py", line 1473, in wsgi_app
    response = self.full_dispatch_request()
               ^^^^^^^^^^^^^^^^^^^^^^^^^^^^
  File "/Users/dhruvshrinet/Desktop/ML PROJECT/.venv/lib/python3.11/site-packages/flask/app.py", line 882, in full_dispatch_request
    rv = self.handle_user_exception(e)
         ^^^^^^^^^^^^^^^^^^^^^^^^^^^^^
  File "/Users/dhruvshrinet/Desktop/ML PROJECT/.venv/lib/python3.11/site-packages/flask/app.py", line 880, in full_dispatch_request
    rv = self.dispatch_request()
         ^^^^^^^^^^^^^^^^^^^^^^^
  File "/Users/dhruvshrinet/Desktop/ML PROJECT/.venv/lib/python3.11/site-packages/flask/app.py", line 865, in dispatch_request
    return self.ensure_sync(self.view_functions[rule.endpoint])(**view_args)  # type: ignore[no-any-return]
           ^^^^^^^^^^^^^^^^^^^^^^^^^^^^^^^^^^^^^^^^^^^^^^^^^^^^^^^^^^^^^^^^^
  File "/Users/dhruvshrinet/Desktop/ML PROJECT/app.py", line 37, in predict_datapoint
    results=predict_pipeline.predict(pred_df)
            ^^^^^^^^^^^^^^^^^^^^^^^^^^^^^^^^^
  File "/Users/dhruvshrinet/Desktop/ML PROJECT/src/pipeline/predict_pipeline.py", line 20, in predict
    raise CustomException(e,sys)
src.exception.CustomException: Error occured in python script [/Users/dhruvshrinet/Desktop/ML PROJECT/src/pipeline/predict_pipeline.py] line number[15] error message[Error occured in python script [/Users/dhruvshrinet/Desktop/ML PROJECT/src/utils.py] line number[56] error message[[Errno 2] No such file or directory: 'artifacts/preprocessor.pkl']]
[2024-11-15 20:41:02,695] 97 werkzeug - INFO - 127.0.0.1 - - [15/Nov/2024 20:41:02] "[35m[1mPOST /predictdata HTTP/1.1[0m" 500 -
[2024-11-15 20:41:33,392] 97 werkzeug - INFO - 127.0.0.1 - - [15/Nov/2024 20:41:33] "GET /predictdata HTTP/1.1" 200 -
[2024-11-15 20:41:48,460] 838 app - ERROR - Exception on /predictdata [POST]
Traceback (most recent call last):
  File "/Users/dhruvshrinet/Desktop/ML PROJECT/src/utils.py", line 56, in load_object
    with open(file_path, "rb") as file_obj:
         ^^^^^^^^^^^^^^^^^^^^^
FileNotFoundError: [Errno 2] No such file or directory: 'artifacts/preprocessor.pkl'

During handling of the above exception, another exception occurred:

Traceback (most recent call last):
  File "/Users/dhruvshrinet/Desktop/ML PROJECT/src/pipeline/predict_pipeline.py", line 15, in predict
    preprocessor = load_object(file_path=preprocessor_path)
                   ^^^^^^^^^^^^^^^^^^^^^^^^^^^^^^^^^^^^^^^^
  File "/Users/dhruvshrinet/Desktop/ML PROJECT/src/utils.py", line 60, in load_object
    raise CustomException(e, sys)
src.exception.CustomException: Error occured in python script [/Users/dhruvshrinet/Desktop/ML PROJECT/src/utils.py] line number[56] error message[[Errno 2] No such file or directory: 'artifacts/preprocessor.pkl']

During handling of the above exception, another exception occurred:

Traceback (most recent call last):
  File "/Users/dhruvshrinet/Desktop/ML PROJECT/.venv/lib/python3.11/site-packages/flask/app.py", line 1473, in wsgi_app
    response = self.full_dispatch_request()
               ^^^^^^^^^^^^^^^^^^^^^^^^^^^^
  File "/Users/dhruvshrinet/Desktop/ML PROJECT/.venv/lib/python3.11/site-packages/flask/app.py", line 882, in full_dispatch_request
    rv = self.handle_user_exception(e)
         ^^^^^^^^^^^^^^^^^^^^^^^^^^^^^
  File "/Users/dhruvshrinet/Desktop/ML PROJECT/.venv/lib/python3.11/site-packages/flask/app.py", line 880, in full_dispatch_request
    rv = self.dispatch_request()
         ^^^^^^^^^^^^^^^^^^^^^^^
  File "/Users/dhruvshrinet/Desktop/ML PROJECT/.venv/lib/python3.11/site-packages/flask/app.py", line 865, in dispatch_request
    return self.ensure_sync(self.view_functions[rule.endpoint])(**view_args)  # type: ignore[no-any-return]
           ^^^^^^^^^^^^^^^^^^^^^^^^^^^^^^^^^^^^^^^^^^^^^^^^^^^^^^^^^^^^^^^^^
  File "/Users/dhruvshrinet/Desktop/ML PROJECT/app.py", line 37, in predict_datapoint
    results=predict_pipeline.predict(pred_df)
            ^^^^^^^^^^^^^^^^^^^^^^^^^^^^^^^^^
  File "/Users/dhruvshrinet/Desktop/ML PROJECT/src/pipeline/predict_pipeline.py", line 20, in predict
    except Exception as e:
        ^^^^^^^^^^^^^^^^^^^
src.exception.CustomException: Error occured in python script [/Users/dhruvshrinet/Desktop/ML PROJECT/src/pipeline/predict_pipeline.py] line number[15] error message[Error occured in python script [/Users/dhruvshrinet/Desktop/ML PROJECT/src/utils.py] line number[56] error message[[Errno 2] No such file or directory: 'artifacts/preprocessor.pkl']]
[2024-11-15 20:41:48,461] 97 werkzeug - INFO - 127.0.0.1 - - [15/Nov/2024 20:41:48] "[35m[1mPOST /predictdata HTTP/1.1[0m" 500 -
