[2024-11-16 20:21:55,525] 97 werkzeug - INFO - [31m[1mWARNING: This is a development server. Do not use it in a production deployment. Use a production WSGI server instead.[0m
 * Running on all addresses (0.0.0.0)
 * Running on http://127.0.0.1:5050
 * Running on http://140.203.84.251:5050
[2024-11-16 20:21:55,526] 97 werkzeug - INFO - [33mPress CTRL+C to quit[0m
[2024-11-16 20:22:00,921] 97 werkzeug - INFO - 127.0.0.1 - - [16/Nov/2024 20:22:00] "GET / HTTP/1.1" 200 -
[2024-11-16 20:22:04,325] 97 werkzeug - INFO - 127.0.0.1 - - [16/Nov/2024 20:22:04] "GET /predictdata HTTP/1.1" 200 -
[2024-11-16 20:22:20,067] 838 app - ERROR - Exception on /predictdata [POST]
Traceback (most recent call last):
  File "/Users/dhruvshrinet/Desktop/ML PROJECT/src/utils.py", line 56, in load_object
    with open(file_path, "rb") as file_obj:
         ^^^^^^^^^^^^^^^^^^^^^
FileNotFoundError: [Errno 2] No such file or directory: 'artifacts/preprocessor.pkl'

During handling of the above exception, another exception occurred:

Traceback (most recent call last):
  File "/Users/dhruvshrinet/Desktop/ML PROJECT/src/pipeline/predict_pipeline.py", line 16, in predict
    preprocessor=load_object(file_path=preprocessor_path)
                 ^^^^^^^^^^^^^^^^^^^^^^^^^^^^^^^^^^^^^^^^
  File "/Users/dhruvshrinet/Desktop/ML PROJECT/src/utils.py", line 60, in load_object
    raise CustomException(e, sys)
src.exception.CustomException: Error occured in python script [/Users/dhruvshrinet/Desktop/ML PROJECT/src/utils.py] line number[56] error message[[Errno 2] No such file or directory: 'artifacts/preprocessor.pkl']

During handling of the above exception, another exception occurred:

Traceback (most recent call last):
  File "/Users/dhruvshrinet/Desktop/ML PROJECT/.venv/lib/python3.11/site-packages/flask/app.py", line 1473, in wsgi_app
    response = self.full_dispatch_request()
               ^^^^^^^^^^^^^^^^^^^^^^^^^^^^
  File "/Users/dhruvshrinet/Desktop/ML PROJECT/.venv/lib/python3.11/site-packages/flask/app.py", line 882, in full_dispatch_request
    rv = self.handle_user_exception(e)
         ^^^^^^^^^^^^^^^^^^^^^^^^^^^^^
  File "/Users/dhruvshrinet/Desktop/ML PROJECT/.venv/lib/python3.11/site-packages/flask/app.py", line 880, in full_dispatch_request
    rv = self.dispatch_request()
         ^^^^^^^^^^^^^^^^^^^^^^^
  File "/Users/dhruvshrinet/Desktop/ML PROJECT/.venv/lib/python3.11/site-packages/flask/app.py", line 865, in dispatch_request
    return self.ensure_sync(self.view_functions[rule.endpoint])(**view_args)  # type: ignore[no-any-return]
           ^^^^^^^^^^^^^^^^^^^^^^^^^^^^^^^^^^^^^^^^^^^^^^^^^^^^^^^^^^^^^^^^^
  File "/Users/dhruvshrinet/Desktop/ML PROJECT/app.py", line 37, in predict_datapoint
    results=predict_pipeline.predict(pred_df)
            ^^^^^^^^^^^^^^^^^^^^^^^^^^^^^^^^^
  File "/Users/dhruvshrinet/Desktop/ML PROJECT/src/pipeline/predict_pipeline.py", line 23, in predict
    raise CustomException(e,sys)
src.exception.CustomException: Error occured in python script [/Users/dhruvshrinet/Desktop/ML PROJECT/src/pipeline/predict_pipeline.py] line number[16] error message[Error occured in python script [/Users/dhruvshrinet/Desktop/ML PROJECT/src/utils.py] line number[56] error message[[Errno 2] No such file or directory: 'artifacts/preprocessor.pkl']]
[2024-11-16 20:22:20,069] 97 werkzeug - INFO - 127.0.0.1 - - [16/Nov/2024 20:22:20] "[35m[1mPOST /predictdata HTTP/1.1[0m" 500 -
[2024-11-16 20:24:43,357] 838 app - ERROR - Exception on /predictdata [POST]
Traceback (most recent call last):
  File "/Users/dhruvshrinet/Desktop/ML PROJECT/src/utils.py", line 56, in load_object
    with open(file_path, "rb") as file_obj:
         ^^^^^^^^^^^^^^^^^^^^^
FileNotFoundError: [Errno 2] No such file or directory: 'artifacts/preprocessor.pkl'

During handling of the above exception, another exception occurred:

Traceback (most recent call last):
  File "/Users/dhruvshrinet/Desktop/ML PROJECT/src/pipeline/predict_pipeline.py", line 16, in predict
    preprocessor=load_object(file_path=preprocessor_path)
                 ^^^^^^^^^^^^^^^^^^^^^^^^^^^^^^^^^^^^^^^^
  File "/Users/dhruvshrinet/Desktop/ML PROJECT/src/utils.py", line 60, in load_object
    raise CustomException(e, sys)
src.exception.CustomException: Error occured in python script [/Users/dhruvshrinet/Desktop/ML PROJECT/src/utils.py] line number[56] error message[[Errno 2] No such file or directory: 'artifacts/preprocessor.pkl']

During handling of the above exception, another exception occurred:

Traceback (most recent call last):
  File "/Users/dhruvshrinet/Desktop/ML PROJECT/.venv/lib/python3.11/site-packages/flask/app.py", line 1473, in wsgi_app
    response = self.full_dispatch_request()
               ^^^^^^^^^^^^^^^^^^^^^^^^^^^^
  File "/Users/dhruvshrinet/Desktop/ML PROJECT/.venv/lib/python3.11/site-packages/flask/app.py", line 882, in full_dispatch_request
    rv = self.handle_user_exception(e)
         ^^^^^^^^^^^^^^^^^^^^^^^^^^^^^
  File "/Users/dhruvshrinet/Desktop/ML PROJECT/.venv/lib/python3.11/site-packages/flask/app.py", line 880, in full_dispatch_request
    rv = self.dispatch_request()
         ^^^^^^^^^^^^^^^^^^^^^^^
  File "/Users/dhruvshrinet/Desktop/ML PROJECT/.venv/lib/python3.11/site-packages/flask/app.py", line 865, in dispatch_request
    return self.ensure_sync(self.view_functions[rule.endpoint])(**view_args)  # type: ignore[no-any-return]
           ^^^^^^^^^^^^^^^^^^^^^^^^^^^^^^^^^^^^^^^^^^^^^^^^^^^^^^^^^^^^^^^^^
  File "/Users/dhruvshrinet/Desktop/ML PROJECT/app.py", line 37, in predict_datapoint
    results=predict_pipeline.predict(pred_df)
            ^^^^^^^^^^^^^^^^^^^^^^^^^^^^^^^^^
  File "/Users/dhruvshrinet/Desktop/ML PROJECT/src/pipeline/predict_pipeline.py", line 23, in predict
    raise CustomException(e,sys)
src.exception.CustomException: Error occured in python script [/Users/dhruvshrinet/Desktop/ML PROJECT/src/pipeline/predict_pipeline.py] line number[16] error message[Error occured in python script [/Users/dhruvshrinet/Desktop/ML PROJECT/src/utils.py] line number[56] error message[[Errno 2] No such file or directory: 'artifacts/preprocessor.pkl']]
[2024-11-16 20:24:43,360] 97 werkzeug - INFO - 127.0.0.1 - - [16/Nov/2024 20:24:43] "[35m[1mPOST /predictdata HTTP/1.1[0m" 500 -
[2024-11-16 20:24:46,963] 97 werkzeug - INFO - 127.0.0.1 - - [16/Nov/2024 20:24:46] "GET /predictdata HTTP/1.1" 200 -
[2024-11-16 20:24:48,749] 97 werkzeug - INFO - 127.0.0.1 - - [16/Nov/2024 20:24:48] "GET /predictdata HTTP/1.1" 200 -
[2024-11-16 20:24:51,640] 97 werkzeug - INFO - 127.0.0.1 - - [16/Nov/2024 20:24:51] "GET /predictdata HTTP/1.1" 200 -
[2024-11-16 20:24:54,096] 838 app - ERROR - Exception on /predictdata [POST]
Traceback (most recent call last):
  File "/Users/dhruvshrinet/Desktop/ML PROJECT/src/utils.py", line 56, in load_object
    with open(file_path, "rb") as file_obj:
         ^^^^^^^^^^^^^^^^^^^^^
FileNotFoundError: [Errno 2] No such file or directory: 'artifacts/preprocessor.pkl'

During handling of the above exception, another exception occurred:

Traceback (most recent call last):
  File "/Users/dhruvshrinet/Desktop/ML PROJECT/src/pipeline/predict_pipeline.py", line 16, in predict
    preprocessor=load_object(file_path=preprocessor_path)
                 ^^^^^^^^^^^^^^^^^^^^^^^^^^^^^^^^^^^^^^^^
  File "/Users/dhruvshrinet/Desktop/ML PROJECT/src/utils.py", line 60, in load_object
    raise CustomException(e, sys)
src.exception.CustomException: Error occured in python script [/Users/dhruvshrinet/Desktop/ML PROJECT/src/utils.py] line number[56] error message[[Errno 2] No such file or directory: 'artifacts/preprocessor.pkl']

During handling of the above exception, another exception occurred:

Traceback (most recent call last):
  File "/Users/dhruvshrinet/Desktop/ML PROJECT/.venv/lib/python3.11/site-packages/flask/app.py", line 1473, in wsgi_app
    response = self.full_dispatch_request()
               ^^^^^^^^^^^^^^^^^^^^^^^^^^^^
  File "/Users/dhruvshrinet/Desktop/ML PROJECT/.venv/lib/python3.11/site-packages/flask/app.py", line 882, in full_dispatch_request
    rv = self.handle_user_exception(e)
         ^^^^^^^^^^^^^^^^^^^^^^^^^^^^^
  File "/Users/dhruvshrinet/Desktop/ML PROJECT/.venv/lib/python3.11/site-packages/flask/app.py", line 880, in full_dispatch_request
    rv = self.dispatch_request()
         ^^^^^^^^^^^^^^^^^^^^^^^
  File "/Users/dhruvshrinet/Desktop/ML PROJECT/.venv/lib/python3.11/site-packages/flask/app.py", line 865, in dispatch_request
    return self.ensure_sync(self.view_functions[rule.endpoint])(**view_args)  # type: ignore[no-any-return]
           ^^^^^^^^^^^^^^^^^^^^^^^^^^^^^^^^^^^^^^^^^^^^^^^^^^^^^^^^^^^^^^^^^
  File "/Users/dhruvshrinet/Desktop/ML PROJECT/app.py", line 37, in predict_datapoint
    results=predict_pipeline.predict(pred_df)
            ^^^^^^^^^^^^^^^^^^^^^^^^^^^^^^^^^
  File "/Users/dhruvshrinet/Desktop/ML PROJECT/src/pipeline/predict_pipeline.py", line 23, in predict
    raise CustomException(e,sys)
src.exception.CustomException: Error occured in python script [/Users/dhruvshrinet/Desktop/ML PROJECT/src/pipeline/predict_pipeline.py] line number[16] error message[Error occured in python script [/Users/dhruvshrinet/Desktop/ML PROJECT/src/utils.py] line number[56] error message[[Errno 2] No such file or directory: 'artifacts/preprocessor.pkl']]
[2024-11-16 20:24:54,097] 97 werkzeug - INFO - 127.0.0.1 - - [16/Nov/2024 20:24:54] "[35m[1mPOST /predictdata HTTP/1.1[0m" 500 -
